Workbook

Sheet Personne
A1: Nom | B1: Prenom | C1: MailPerso | D1: MailPro | E1: InterneOuExterne | F1: Ville | G1: CodeINSEE | H1: IdHALL
A2: Hooper | B2: Quinn | C2: quinn@yahoo.fr | D2: q_hooper6540@univsmb.fr | E2: True | F2: Epron | G2: {=IFERROR(TEXT(INT(RAND()*2+1),"0") & TEXT(INT(RAND()*55)+1955,"00") & TEXT(INT(RAND()*12)+1,"00") & INDEX(CodesINSEE!A:A,MATCH(F2,CodesINSEE!B:B,0)) & INDEX([1]Personne!A:A,INT(RAND()*39193)+1) & TEXT(INT(RAND()*999)+1,"000"),"Erreur")} -> 119650814242660 | H2: ="hal-" & TEXT(INT(RAND()*(10^(7+INT(RAND()*2)))), "00000000") -> hal-09155788
A3: Reynolds | B3: Nero | C3: nero@gmail.com | D3: rnero@univsmb.fr | E3: False | F3: Caen | G3: {=IFERROR(TEXT(INT(RAND()*2+1),"0") & TEXT(INT(RAND()*55)+1955,"00") & TEXT(INT(RAND()*12)+1,"00") & INDEX(CodesINSEE!A:A,MATCH(F3,CodesINSEE!B:B,0)) & INDEX([1]Personne!A:A,INT(RAND()*39193)+1) & TEXT(INT(RAND()*999)+1,"000"),"Erreur")} -> 119720614118403 | H3: ="hal-" & TEXT(INT(RAND()*(10^(7+INT(RAND()*2)))), "00000000") -> hal-01742697
A4: Castillo | B4: Mariam | C4: mariam@gmail.com | D4: m.castillo2039@univsmb.fr | E4: True | F4: Dole | G4: {=IFERROR(TEXT(INT(RAND()*2+1),"0") & TEXT(INT(RAND()*55)+1955,"00") & TEXT(INT(RAND()*12)+1,"00") & INDEX(CodesINSEE!A:A,MATCH(F4,CodesINSEE!B:B,0)) & INDEX([1]Personne!A:A,INT(RAND()*39193)+1) & TEXT(INT(RAND()*999)+1,"000"),"Erreur")} -> 220030139198051 | H4: ="hal-" & TEXT(INT(RAND()*(10^(7+INT(RAND()*2)))), "00000000") -> hal-04346970
A5: Kinney | B5: Carlos | C5: carlos9787@yahoo.com | D5: carlos_kinney@univsmb.fr | E5: False | F5: Agen | G5: {=IFERROR(TEXT(INT(RAND()*2+1),"0") & TEXT(INT(RAND()*55)+1955,"00") & TEXT(INT(RAND()*12)+1,"00") & INDEX(CodesINSEE!A:A,MATCH(F5,CodesINSEE!B:B,0)) & INDEX([1]Personne!A:A,INT(RAND()*39193)+1) & TEXT(INT(RAND()*999)+1,"000"),"Erreur")} -> 119870147001824 | H5: ="hal-" & TEXT(INT(RAND()*(10^(7+INT(RAND()*2)))), "00000000") -> hal-08726251
A6: Hoover | B6: Felix | C6: felix@gmail.fr | D6: felix_hoover@univsmb.fr | E6: True | F6: Bastia | G6: {=IFERROR(TEXT(INT(RAND()*2+1),"0") & TEXT(INT(RAND()*55)+1955,"00") & TEXT(INT(RAND()*12)+1,"00") & INDEX(CodesINSEE!A:A,MATCH(F6,CodesINSEE!B:B,0)) & INDEX([1]Personne!A:A,INT(RAND()*39193)+1) & TEXT(INT(RAND()*999)+1,"000"),"Erreur")} -> 21993092B033957 | H6: ="hal-" & TEXT(INT(RAND()*(10^(7+INT(RAND()*2)))), "00000000") -> hal-01144543
A7: Sanford | B7: Clayton | C7: clayton6540@gmail.fr | D7: clayton-sanford@univsmb.fr | E7: True | F7: Perpignan | G7: {=IFERROR(TEXT(INT(RAND()*2+1),"0") & TEXT(INT(RAND()*55)+1955,"00") & TEXT(INT(RAND()*12)+1,"00") & INDEX(CodesINSEE!A:A,MATCH(F7,CodesINSEE!B:B,0)) & INDEX([1]Personne!A:A,INT(RAND()*39193)+1) & TEXT(INT(RAND()*999)+1,"000"),"Erreur")} -> 219800466136262 | H7: ="hal-" & TEXT(INT(RAND()*(10^(7+INT(RAND()*2)))), "00000000") -> hal-07037567
A8: Jones | B8: Josiah | C8: josiah@yahoo.com | D8: jones_josiah8547@univsmb.fr | E8: False | F8: Nevers | G8: {=IFERROR(TEXT(INT(RAND()*2+1),"0") & TEXT(INT(RAND()*55)+1955,"00") & TEXT(INT(RAND()*12)+1,"00") & INDEX(CodesINSEE!A:A,MATCH(F8,CodesINSEE!B:B,0)) & INDEX([1]Personne!A:A,INT(RAND()*39193)+1) & TEXT(INT(RAND()*999)+1,"000"),"Erreur")} -> 219910658194554 | H8: ="hal-" & TEXT(INT(RAND()*(10^(7+INT(RAND()*2)))), "00000000") -> hal-67685475
A9: Bolton | B9: Shellie | C9: shellie@gmail.com | D9: b_shellie@univsmb.fr | E9: False | F9: Tours | G9: {=IFERROR(TEXT(INT(RAND()*2+1),"0") & TEXT(INT(RAND()*55)+1955,"00") & TEXT(INT(RAND()*12)+1,"00") & INDEX(CodesINSEE!A:A,MATCH(F9,CodesINSEE!B:B,0)) & INDEX([1]Personne!A:A,INT(RAND()*39193)+1) & TEXT(INT(RAND()*999)+1,"000"),"Erreur")} -> 119760837261052 | H9: ="hal-" & TEXT(INT(RAND()*(10^(7+INT(RAND()*2)))), "00000000") -> hal-09841064
A10: Lancaster | B10: Skyler | C10: skyler1943@gmail.com | D10: lskyler@univsmb.fr | E10: False | F10: Vitry sur Seine | G10: {=IFERROR(TEXT(INT(RAND()*2+1),"0") & TEXT(INT(RAND()*55)+1955,"00") & TEXT(INT(RAND()*12)+1,"00") & INDEX(CodesINSEE!A:A,MATCH(F10,CodesINSEE!B:B,0)) & INDEX([1]Personne!A:A,INT(RAND()*39193)+1) & TEXT(INT(RAND()*999)+1,"000"),"Erreur")} -> 119930494081104 | H10: ="hal-" & TEXT(INT(RAND()*(10^(7+INT(RAND()*2)))), "00000000") -> hal-03053068
A11: Alford | B11: Kasimir | C11: kasimir@gmail.fr | D11: alford-kasimir@univsmb.fr | E11: False | F11: Saint Lo | G11: {=IFERROR(TEXT(INT(RAND()*2+1),"0") & TEXT(INT(RAND()*55)+1955,"00") & TEXT(INT(RAND()*12)+1,"00") & INDEX(CodesINSEE!A:A,MATCH(F11,CodesINSEE!B:B,0)) & INDEX([1]Personne!A:A,INT(RAND()*39193)+1) & TEXT(INT(RAND()*999)+1,"000"),"Erreur")} -> 219881250502039 | H11: ="hal-" & TEXT(INT(RAND()*(10^(7+INT(RAND()*2)))), "00000000") -> hal-08264891
A12: Donaldson | B12: Aretha | C12: aretha@yahoo.com | D12: donaldson_aretha9529@univsmb.fr | E12: False | F12: Evreux | G12: {=IFERROR(TEXT(INT(RAND()*2+1),"0") & TEXT(INT(RAND()*55)+1955,"00") & TEXT(INT(RAND()*12)+1,"00") & INDEX(CodesINSEE!A:A,MATCH(F12,CodesINSEE!B:B,0)) & INDEX([1]Personne!A:A,INT(RAND()*39193)+1) & TEXT(INT(RAND()*999)+1,"000"),"Erreur")} -> 119680527229806 | H12: ="hal-" & TEXT(INT(RAND()*(10^(7+INT(RAND()*2)))), "00000000") -> hal-16948699
A13: Nash | B13: Yoshi | C13: yoshi5226@gmail.fr | D13: yoshi_nash788@univsmb.fr | E13: True | F13: Dole | G13: {=IFERROR(TEXT(INT(RAND()*2+1),"0") & TEXT(INT(RAND()*55)+1955,"00") & TEXT(INT(RAND()*12)+1,"00") & INDEX(CodesINSEE!A:A,MATCH(F13,CodesINSEE!B:B,0)) & INDEX([1]Personne!A:A,INT(RAND()*39193)+1) & TEXT(INT(RAND()*999)+1,"000"),"Erreur")} -> 219661239198406 | H13: ="hal-" & TEXT(INT(RAND()*(10^(7+INT(RAND()*2)))), "00000000") -> hal-03022707
... A101: Alvarado | B101: Bert | C101: bert@yahoo.com | D101: alvarado_bert@univsmb.fr | E101: False | F101: Evreux | G101: {=IFERROR(TEXT(INT(RAND()*2+1),"0") & TEXT(INT(RAND()*55)+1955,"00") & TEXT(INT(RAND()*12)+1,"00") & INDEX(CodesINSEE!A:A,MATCH(F101,CodesINSEE!B:B,0)) & INDEX([1]Personne!A:A,INT(RAND()*39193)+1) & TEXT(INT(RAND()*999)+1,"000"),"Erreur")} -> 119940827229221 | H101: ="hal-" & TEXT(INT(RAND()*(10^(7+INT(RAND()*2)))), "00000000") -> hal-06942631

Sheet CodesINSEE
A1: ListeINSEE | G1: Ville
A2: 1001 | B2: =PROPER(G2) -> Abergement Clemenciat | G2: ABERGEMENT CLEMENCIAT
A3: 1002 | B3: =PROPER(G3) -> Abergement De Varey | G3: ABERGEMENT DE VAREY
A4: 1004 | B4: =PROPER(G4) -> Amberieu En Bugey | G4: AMBERIEU EN BUGEY
A5: 1005 | B5: =PROPER(G5) -> Amberieux En Dombes | G5: AMBERIEUX EN DOMBES
A6: 1006 | B6: =PROPER(G6) -> Ambleon | G6: AMBLEON
A7: 1007 | B7: =PROPER(G7) -> Ambronay | G7: AMBRONAY
A8: 1008 | B8: =PROPER(G8) -> Ambutrix | G8: AMBUTRIX
A9: 1009 | B9: =PROPER(G9) -> Andert Et Condon | G9: ANDERT ET CONDON
A10: 1010 | B10: =PROPER(G10) -> Anglefort | G10: ANGLEFORT
A11: 1011 | B11: =PROPER(G11) -> Apremont | G11: APREMONT
A12: 1012 | B12: =PROPER(G12) -> Aranc | G12: ARANC
A13: 1013 | B13: =PROPER(G13) -> Arandas | G13: ARANDAS
... A2634: 8164 | B2634: =PROPER(G2634) -> Falaise | G2634: FALAISE
A2635: 8165 | B2635: =PROPER(G2635) -> Faux | G2635: FALSE
A2636: 8166 | B2636: =PROPER(G2636) -> Fepin | G2636: FEPIN
A2637: 8167 | B2637: =PROPER(G2637) -> Feree | G2637: FEREE
A2638: 8168 | B2638: =PROPER(G2638) -> Ferte Sur Chiers | G2638: FERTE SUR CHIERS
A2639: 8169 | B2639: =PROPER(G2639) -> Flaignes Havys | G2639: FLAIGNES HAVYS
A2640: 8170 | B2640: =PROPER(G2640) -> Fleigneux | G2640: FLEIGNEUX
A2641: 8171 | B2641: =PROPER(G2641) -> Fleville | G2641: FLEVILLE
A2642: 8172 | B2642: =PROPER(G2642) -> Fligny | G2642: FLIGNY
A2643: 8173 | B2643: =PROPER(G2643) -> Flize | G2643: FLIZE
A2644: 8173 | B2644: =PROPER(G2644) -> Flize | G2644: FLIZE
A2645: 8174 | B2645: =PROPER(G2645) -> Floing | G2645: FLOING
A2646: 8175 | B2646: =PROPER(G2646) -> Foisches | G2646: FOISCHES
A2647: 8176 | B2647: =PROPER(G2647) -> Fosse | G2647: FOSSE
... A8611: 24176 | B8611: =PROPER(G8611) -> Faurilles | G8611: FAURILLES
A8612: 24177 | B8612: =PROPER(G8612) -> Faux | G8612: FALSE
A8613: 24179 | B8613: =PROPER(G8613) -> Feuillade | G8613: FEUILLADE
A8614: 24180 | B8614: =PROPER(G8614) -> Firbeix | G8614: FIRBEIX
A8615: 24182 | B8615: =PROPER(G8615) -> Fleix | G8615: FLEIX
A8616: 24183 | B8616: =PROPER(G8616) -> Fleurac | G8616: FLEURAC
A8617: 24184 | B8617: =PROPER(G8617) -> Florimont Gaumier | G8617: FLORIMONT GAUMIER
A8618: 24186 | B8618: =PROPER(G8618) -> Fonroque | G8618: FONROQUE
A8619: 24188 | B8619: =PROPER(G8619) -> Fossemagne | G8619: FOSSEMAGNE
A8620: 24189 | B8620: =PROPER(G8620) -> Fougueyrolles | G8620: FOUGUEYROLLES
A8621: 24190 | B8621: =PROPER(G8621) -> Fouleix | G8621: FOULEIX
A8622: 24191 | B8622: =PROPER(G8622) -> Fraisse | G8622: FRAISSE
A8623: 24192 | B8623: =PROPER(G8623) -> Gabillou | G8623: GABILLOU
...
